Workbook

Sheet Summary Deshboard
A1: Dashboard Structure | D1: ME-wise Summary | J1: Product Type Summary
A2: Total Customers | B2: =COUNTA('Master sheet'!C:C)-1 -> 578 | D2: =IFERROR(__xludf.DUMMYFUNCTION("QUERY('Master sheet'!A:H,""select H,count(H) where H is not null group by H label count(H) 'Customers Onboarded'"",1)"),"Name of ME Who Onboarded") -> Name of ME Who Onboarded | E2: =IFERROR(__xludf.DUMMYFUNCTION("""COMPUTED_VALUE"""),"Customers Onboarded") -> Customers Onboarded | J2: =IFERROR(__xludf.DUMMYFUNCTION("QUERY('Master sheet'!A:H,""select F,count(F) where F is not null group by F"",1)"),"Product Type") -> Product Type | K2: =IFERROR(__xludf.DUMMYFUNCTION("""COMPUTED_VALUE"""),"count Product Type") -> count Product Type
D3: =IFERROR(__xludf.DUMMYFUNCTION("""COMPUTED_VALUE"""),"Abhishek Malviye") -> Abhishek Malviye | E3: =IFERROR(__xludf.DUMMYFUNCTION("""COMPUTED_VALUE"""),5) -> 5 | J3: =IFERROR(__xludf.DUMMYFUNCTION("""COMPUTED_VALUE"""),"ADVANCED CUSTOMER") -> ADVANCED CUSTOMER | K3: =IFERROR(__xludf.DUMMYFUNCTION("""COMPUTED_VALUE"""),72) -> 72
A4: Total B2B | B4: =COUNTIF('Master sheet'!G:G,"B2B") -> 3 | D4: =IFERROR(__xludf.DUMMYFUNCTION("""COMPUTED_VALUE"""),"Anil kumar kayasth") -> Anil kumar kayasth | E4: =IFERROR(__xludf.DUMMYFUNCTION("""COMPUTED_VALUE"""),11) -> 11 | J4: =IFERROR(__xludf.DUMMYFUNCTION("""COMPUTED_VALUE"""),"BNPL") -> BNPL | K4: =IFERROR(__xludf.DUMMYFUNCTION("""COMPUTED_VALUE"""),2) -> 2
D5: =IFERROR(__xludf.DUMMYFUNCTION("""COMPUTED_VALUE"""),"Ashok Jatiya") -> Ashok Jatiya | E5: =IFERROR(__xludf.DUMMYFUNCTION("""COMPUTED_VALUE"""),1) -> 1 | J5: =IFERROR(__xludf.DUMMYFUNCTION("""COMPUTED_VALUE"""),"BNPL SPEED ") -> BNPL SPEED | K5: =IFERROR(__xludf.DUMMYFUNCTION("""COMPUTED_VALUE"""),1) -> 1
A6: Total B2C | B6: =COUNTIF('Master sheet'!G:G,"B2C") -> 575 | D6: =IFERROR(__xludf.DUMMYFUNCTION("""COMPUTED_VALUE"""),"Ayush Gupta") -> Ayush Gupta | E6: =IFERROR(__xludf.DUMMYFUNCTION("""COMPUTED_VALUE"""),5) -> 5 | J6: =IFERROR(__xludf.DUMMYFUNCTION("""COMPUTED_VALUE"""),"BNPL SPEED POST") -> BNPL SPEED POST | K6: =IFERROR(__xludf.DUMMYFUNCTION("""COMPUTED_VALUE"""),1) -> 1
D7: =IFERROR(__xludf.DUMMYFUNCTION("""COMPUTED_VALUE"""),"BRIJESH SHRIVAS") -> BRIJESH SHRIVAS | E7: =IFERROR(__xludf.DUMMYFUNCTION("""COMPUTED_VALUE"""),9) -> 9 | J7: =IFERROR(__xludf.DUMMYFUNCTION("""COMPUTED_VALUE"""),"BNPL speed post") -> BNPL speed post | K7: =IFERROR(__xludf.DUMMYFUNCTION("""COMPUTED_VALUE"""),2) -> 2
A8: Today's Onboarding | B8: =COUNTIF('Master sheet'!E:E,TODAY()) -> 0 | D8: =IFERROR(__xludf.DUMMYFUNCTION("""COMPUTED_VALUE"""),"DEEPIKA VERMA") -> DEEPIKA VERMA | E8: =IFERROR(__xludf.DUMMYFUNCTION("""COMPUTED_VALUE"""),2) -> 2 | J8: =IFERROR(__xludf.DUMMYFUNCTION("""COMPUTED_VALUE"""),"FASHION ") -> FASHION | K8: =IFERROR(__xludf.DUMMYFUNCTION("""COMPUTED_VALUE"""),1) -> 1
D9: =IFERROR(__xludf.DUMMYFUNCTION("""COMPUTED_VALUE"""),"DURGA SHANKAR GARASIYA") -> DURGA SHANKAR GARASIYA | E9: =IFERROR(__xludf.DUMMYFUNCTION("""COMPUTED_VALUE"""),17) -> 17 | J9: =IFERROR(__xludf.DUMMYFUNCTION("""COMPUTED_VALUE"""),"FMCG") -> FMCG | K9: =IFERROR(__xludf.DUMMYFUNCTION("""COMPUTED_VALUE"""),1) -> 1
A10: This Month Onboarding | B10: =COUNTIFS('Master sheet'!E:E,">="&EOMONTH(TODAY(),-1)+1,'Master sheet'!E:E,"<="&EOMONTH(TODAY(),0)) -> 0 | D10: =IFERROR(__xludf.DUMMYFUNCTION("""COMPUTED_VALUE"""),"HARSHIT PARMAR") -> HARSHIT PARMAR | E10: =IFERROR(__xludf.DUMMYFUNCTION("""COMPUTED_VALUE"""),6) -> 6 | J10: =IFERROR(__xludf.DUMMYFUNCTION("""COMPUTED_VALUE"""),"HERBVAL PRODUCTS") -> HERBVAL PRODUCTS | K10: =IFERROR(__xludf.DUMMYFUNCTION("""COMPUTED_VALUE"""),2) -> 2
D11: =IFERROR(__xludf.DUMMYFUNCTION("""COMPUTED_VALUE"""),"HEMANT BAGHEL") -> HEMANT BAGHEL | E11: =IFERROR(__xludf.DUMMYFUNCTION("""COMPUTED_VALUE"""),4) -> 4 | J11: =IFERROR(__xludf.DUMMYFUNCTION("""COMPUTED_VALUE"""),"INDIA POST PARCEL CONTRACTUAL ") -> INDIA POST PARCEL CONTRACTUAL | K11: =IFERROR(__xludf.DUMMYFUNCTION("""COMPUTED_VALUE"""),2) -> 2
D12: =IFERROR(__xludf.DUMMYFUNCTION("""COMPUTED_VALUE"""),"HIMMAT SINGH") -> HIMMAT SINGH | E12: =IFERROR(__xludf.DUMMYFUNCTION("""COMPUTED_VALUE"""),22) -> 22 | J12: =IFERROR(__xludf.DUMMYFUNCTION("""COMPUTED_VALUE"""),"INDIAPOST PARCEL CONTRACTUAL") -> INDIAPOST PARCEL CONTRACTUAL | K12: =IFERROR(__xludf.DUMMYFUNCTION("""COMPUTED_VALUE"""),2) -> 2
D13: =IFERROR(__xludf.DUMMYFUNCTION("""COMPUTED_VALUE"""),"JUNAId khan") -> JUNAId khan | E13: =IFERROR(__xludf.DUMMYFUNCTION("""COMPUTED_VALUE"""),1) -> 1 | J13: =IFERROR(__xludf.DUMMYFUNCTION("""COMPUTED_VALUE"""),"INDIAPOST PARCEL CONTRACTUAL ") -> INDIAPOST PARCEL CONTRACTUAL | K13: =IFERROR(__xludf.DUMMYFUNCTION("""COMPUTED_VALUE"""),3) -> 3
D14: =IFERROR(__xludf.DUMMYFUNCTION("""COMPUTED_VALUE"""),"Jalaj Rawat") -> Jalaj Rawat | E14: =IFERROR(__xludf.DUMMYFUNCTION("""COMPUTED_VALUE"""),71) -> 71 | J14: =IFERROR(__xludf.DUMMYFUNCTION("""COMPUTED_VALUE"""),"India Post Parcel Contractual") -> India Post Parcel Contractual | K14: =IFERROR(__xludf.DUMMYFUNCTION("""COMPUTED_VALUE"""),17) -> 17
D15: =IFERROR(__xludf.DUMMYFUNCTION("""COMPUTED_VALUE"""),"Kavita Bhuriya") -> Kavita Bhuriya | E15: =IFERROR(__xludf.DUMMYFUNCTION("""COMPUTED_VALUE"""),2) -> 2 | J15: =IFERROR(__xludf.DUMMYFUNCTION("""COMPUTED_VALUE"""),"Indiapost Parcel Contractual") -> Indiapost Parcel Contractual | K15: =IFERROR(__xludf.DUMMYFUNCTION("""COMPUTED_VALUE"""),45) -> 45
D16: =IFERROR(__xludf.DUMMYFUNCTION("""COMPUTED_VALUE"""),"Kunal Baurasi") -> Kunal Baurasi | E16: =IFERROR(__xludf.DUMMYFUNCTION("""COMPUTED_VALUE"""),4) -> 4 | J16: =IFERROR(__xludf.DUMMYFUNCTION("""COMPUTED_VALUE"""),"International EMS Document") -> International EMS Document | K16: =IFERROR(__xludf.DUMMYFUNCTION("""COMPUTED_VALUE"""),1) -> 1
D17: =IFERROR(__xludf.DUMMYFUNCTION("""COMPUTED_VALUE"""),"NEELESH VERMA") -> NEELESH VERMA | E17: =IFERROR(__xludf.DUMMYFUNCTION("""COMPUTED_VALUE"""),20) -> 20 | J17: =IFERROR(__xludf.DUMMYFUNCTION("""COMPUTED_VALUE"""),"International Tracked Packet Service") -> International Tracked Packet Service | K17: =IFERROR(__xludf.DUMMYFUNCTION("""COMPUTED_VALUE"""),1) -> 1
D18: =IFERROR(__xludf.DUMMYFUNCTION("""COMPUTED_VALUE"""),"Narendra Baviskar") -> Narendra Baviskar | E18: =IFERROR(__xludf.DUMMYFUNCTION("""COMPUTED_VALUE"""),52) -> 52 | J18: =IFERROR(__xludf.DUMMYFUNCTION("""COMPUTED_VALUE"""),"LETTERS") -> LETTERS | K18: =IFERROR(__xludf.DUMMYFUNCTION("""COMPUTED_VALUE"""),10) -> 10
D19: =IFERROR(__xludf.DUMMYFUNCTION("""COMPUTED_VALUE"""),"RAHUL AGRAWAL") -> RAHUL AGRAWAL | E19: =IFERROR(__xludf.DUMMYFUNCTION("""COMPUTED_VALUE"""),43) -> 43 | J19: =IFERROR(__xludf.DUMMYFUNCTION("""COMPUTED_VALUE"""),"LETTES") -> LETTES | K19: =IFERROR(__xludf.DUMMYFUNCTION("""COMPUTED_VALUE"""),1) -> 1
D20: =IFERROR(__xludf.DUMMYFUNCTION("""COMPUTED_VALUE"""),"RAJENDRA PUSHPAD") -> RAJENDRA PUSHPAD | E20: =IFERROR(__xludf.DUMMYFUNCTION("""COMPUTED_VALUE"""),7) -> 7 | J20: =IFERROR(__xludf.DUMMYFUNCTION("""COMPUTED_VALUE"""),"MACHINE GOODS") -> MACHINE GOODS | K20: =IFERROR(__xludf.DUMMYFUNCTION("""COMPUTED_VALUE"""),3) -> 3
D21: =IFERROR(__xludf.DUMMYFUNCTION("""COMPUTED_VALUE"""),"RISHABH SINGH GOUR") -> RISHABH SINGH GOUR | E21: =IFERROR(__xludf.DUMMYFUNCTION("""COMPUTED_VALUE"""),25) -> 25 | J21: =IFERROR(__xludf.DUMMYFUNCTION("""COMPUTED_VALUE"""),"MEDICINES") -> MEDICINES | K21: =IFERROR(__xludf.DUMMYFUNCTION("""COMPUTED_VALUE"""),1) -> 1
D22: =IFERROR(__xludf.DUMMYFUNCTION("""COMPUTED_VALUE"""),"Rahul Panchal") -> Rahul Panchal | E22: =IFERROR(__xludf.DUMMYFUNCTION("""COMPUTED_VALUE"""),37) -> 37 | J22: =IFERROR(__xludf.DUMMYFUNCTION("""COMPUTED_VALUE"""),"Magazine Post") -> Magazine Post | K22: =IFERROR(__xludf.DUMMYFUNCTION("""COMPUTED_VALUE"""),7) -> 7
D23: =IFERROR(__xludf.DUMMYFUNCTION("""COMPUTED_VALUE"""),"Rajendra pushpad") -> Rajendra pushpad | E23: =IFERROR(__xludf.DUMMYFUNCTION("""COMPUTED_VALUE"""),1) -> 1 | J23: =IFERROR(__xludf.DUMMYFUNCTION("""COMPUTED_VALUE"""),"PARCEL") -> PARCEL | K23: =IFERROR(__xludf.DUMMYFUNCTION("""COMPUTED_VALUE"""),5) -> 5
D24: =IFERROR(__xludf.DUMMYFUNCTION("""COMPUTED_VALUE"""),"SANTOSH RATHORE") -> SANTOSH RATHORE | E24: =IFERROR(__xludf.DUMMYFUNCTION("""COMPUTED_VALUE"""),4) -> 4 | J24: =IFERROR(__xludf.DUMMYFUNCTION("""COMPUTED_VALUE"""),"Registered Mails") -> Registered Mails | K24: =IFERROR(__xludf.DUMMYFUNCTION("""COMPUTED_VALUE"""),13) -> 13
D25: =IFERROR(__xludf.DUMMYFUNCTION("""COMPUTED_VALUE"""),"SANTOSH VERMA") -> SANTOSH VERMA | E25: =IFERROR(__xludf.DUMMYFUNCTION("""COMPUTED_VALUE"""),18) -> 18 | J25: =IFERROR(__xludf.DUMMYFUNCTION("""COMPUTED_VALUE"""),"SHOES") -> SHOES | K25: =IFERROR(__xludf.DUMMYFUNCTION("""COMPUTED_VALUE"""),1) -> 1
D26: =IFERROR(__xludf.DUMMYFUNCTION("""COMPUTED_VALUE"""),"Shri Vishal Soni") -> Shri Vishal Soni | E26: =IFERROR(__xludf.DUMMYFUNCTION("""COMPUTED_VALUE"""),40) -> 40 | J26: =IFERROR(__xludf.DUMMYFUNCTION("""COMPUTED_VALUE"""),"SPEED POST AND PARCEL CONTRACTUAL ") -> SPEED POST AND PARCEL CONTRACTUAL | K26: =IFERROR(__xludf.DUMMYFUNCTION("""COMPUTED_VALUE"""),1) -> 1
D27: =IFERROR(__xludf.DUMMYFUNCTION("""COMPUTED_VALUE"""),"Shri Yash Mittal") -> Shri Yash Mittal | E27: =IFERROR(__xludf.DUMMYFUNCTION("""COMPUTED_VALUE"""),52) -> 52 | J27: =IFERROR(__xludf.DUMMYFUNCTION("""COMPUTED_VALUE"""),"SPORTS PRODUCTS") -> SPORTS PRODUCTS | K27: =IFERROR(__xludf.DUMMYFUNCTION("""COMPUTED_VALUE"""),2) -> 2
D28: =IFERROR(__xludf.DUMMYFUNCTION("""COMPUTED_VALUE"""),"Sunil bhojwani") -> Sunil bhojwani | E28: =IFERROR(__xludf.DUMMYFUNCTION("""COMPUTED_VALUE"""),3) -> 3 | J28: =IFERROR(__xludf.DUMMYFUNCTION("""COMPUTED_VALUE"""),"Speed Post") -> Speed Post | K28: =IFERROR(__xludf.DUMMYFUNCTION("""COMPUTED_VALUE"""),29) -> 29
D29: =IFERROR(__xludf.DUMMYFUNCTION("""COMPUTED_VALUE"""),"Surendra Singh") -> Surendra Singh | E29: =IFERROR(__xludf.DUMMYFUNCTION("""COMPUTED_VALUE"""),4) -> 4 | J29: =IFERROR(__xludf.DUMMYFUNCTION("""COMPUTED_VALUE"""),"Speed Post Document") -> Speed Post Document | K29: =IFERROR(__xludf.DUMMYFUNCTION("""COMPUTED_VALUE"""),3) -> 3
D30: =IFERROR(__xludf.DUMMYFUNCTION("""COMPUTED_VALUE"""),"VINEET PATEL") -> VINEET PATEL | E30: =IFERROR(__xludf.DUMMYFUNCTION("""COMPUTED_VALUE"""),24) -> 24 | J30: =IFERROR(__xludf.DUMMYFUNCTION("""COMPUTED_VALUE"""),"Speed Post Parcel Contractual") -> Speed Post Parcel Contractual | K30: =IFERROR(__xludf.DUMMYFUNCTION("""COMPUTED_VALUE"""),1) -> 1
D31: =IFERROR(__xludf.DUMMYFUNCTION("""COMPUTED_VALUE"""),"Vineet Patel") -> Vineet Patel | E31: =IFERROR(__xludf.DUMMYFUNCTION("""COMPUTED_VALUE"""),2) -> 2 | J31: =IFERROR(__xludf.DUMMYFUNCTION("""COMPUTED_VALUE"""),"Speed Post Parcel Domestic") -> Speed Post Parcel Domestic | K31: =IFERROR(__xludf.DUMMYFUNCTION("""COMPUTED_VALUE"""),27) -> 27
D32: =IFERROR(__xludf.DUMMYFUNCTION("""COMPUTED_VALUE"""),"Zuber Ahmed Khan") -> Zuber Ahmed Khan | E32: =IFERROR(__xludf.DUMMYFUNCTION("""COMPUTED_VALUE"""),36) -> 36 | J32: =IFERROR(__xludf.DUMMYFUNCTION("""COMPUTED_VALUE"""),"Speed Post ParcelÂ Domestic") -> Speed Post ParcelÂ Domestic | K32: =IFERROR(__xludf.DUMMYFUNCTION("""COMPUTED_VALUE"""),2) -> 2
D33: =IFERROR(__xludf.DUMMYFUNCTION("""COMPUTED_VALUE"""),"junaid khan") -> junaid khan | E33: =IFERROR(__xludf.DUMMYFUNCTION("""COMPUTED_VALUE"""),13) -> 13 | J33: =IFERROR(__xludf.DUMMYFUNCTION("""COMPUTED_VALUE"""),"Speed Post,Indiapost Parcel Contractual") -> Speed Post,Indiapost Parcel Contractual | K33: =IFERROR(__xludf.DUMMYFUNCTION("""COMPUTED_VALUE"""),1) -> 1
D34: =IFERROR(__xludf.DUMMYFUNCTION("""COMPUTED_VALUE"""),"santosh rathore ") -> santosh rathore | E34: =IFERROR(__xludf.DUMMYFUNCTION("""COMPUTED_VALUE"""),2) -> 2 | J34: =IFERROR(__xludf.DUMMYFUNCTION("""COMPUTED_VALUE"""),"advance customer") -> advance customer | K34: =IFERROR(__xludf.DUMMYFUNCTION("""COMPUTED_VALUE"""),1) -> 1
D35: =IFERROR(__xludf.DUMMYFUNCTION("""COMPUTED_VALUE"""),"sunil bhojwani") -> sunil bhojwani | E35: =IFERROR(__xludf.DUMMYFUNCTION("""COMPUTED_VALUE"""),16) -> 16 | J35: =IFERROR(__xludf.DUMMYFUNCTION("""COMPUTED_VALUE"""),"bnpl-speed post") -> bnpl-speed post | K35: =IFERROR(__xludf.DUMMYFUNCTION("""COMPUTED_VALUE"""),10) -> 10
D36: =IFERROR(__xludf.DUMMYFUNCTION("""COMPUTED_VALUE"""),"vineet Patel ") -> vineet Patel | E36: =IFERROR(__xludf.DUMMYFUNCTION("""COMPUTED_VALUE"""),1) -> 1 | J36: =IFERROR(__xludf.DUMMYFUNCTION("""COMPUTED_VALUE"""),"parcel contractual") -> parcel contractual | K36: =IFERROR(__xludf.DUMMYFUNCTION("""COMPUTED_VALUE"""),1) -> 1
D37: =IFERROR(__xludf.DUMMYFUNCTION("""COMPUTED_VALUE"""),"vineet patel") -> vineet patel | E37: =IFERROR(__xludf.DUMMYFUNCTION("""COMPUTED_VALUE"""),3) -> 3 | J37: =IFERROR(__xludf.DUMMYFUNCTION("""COMPUTED_VALUE"""),"parcel contractual ") -> parcel contractual | K37: =IFERROR(__xludf.DUMMYFUNCTION("""COMPUTED_VALUE"""),4) -> 4
D38: =IFERROR(__xludf.DUMMYFUNCTION("""COMPUTED_VALUE"""),"vineet patel ") -> vineet patel | E38: =IFERROR(__xludf.DUMMYFUNCTION("""COMPUTED_VALUE"""),1) -> 1
A49: Division Summary
A50: =IFERROR(__xludf.DUMMYFUNCTION("QUERY('Master sheet'!A:H,""select B,count(B) where B is not null group by B"",1)"),"Division") -> Division | B50: =IFERROR(__xludf.DUMMYFUNCTION("""COMPUTED_VALUE"""),"count Division") -> count Division
...

Sheet Master sheet
A1: S.No. | B1: Division | C1: Name of Customer | D1: Customer ID | E1: Date of Onboarding | F1: Product Type | G1: B2B Or B2C | H1: Name of ME Who Onboarded
A2: =IFERROR(__xludf.DUMMYFUNCTION("QUERY({'Indore City'!B4:I999;'Indore MFL'!B4:I999;Khandwa!B4:I1000;Mandsaur!B4:I1000;Ratlam!B4:I997;Sehore!B4:I1000;Ujjain!B4:I995;'RMS ID Dn'!B5:I972},""SELECT * WHERE Col1 IS NOT NULL"",0)"),1) -> 1 | B2: =IFERROR(__xludf.DUMMYFUNCTION("""COMPUTED_VALUE"""),"Indore City") -> Indore City | C2: =IFERROR(__xludf.DUMMYFUNCTION("""COMPUTED_VALUE"""),"DRASHTI ENTERPRISES") -> DRASHTI ENTERPRISES | D2: =IFERROR(__xludf.DUMMYFUNCTION("""COMPUTED_VALUE"""),1504860613) -> 1504860613 | E2: =IFERROR(__xludf.DUMMYFUNCTION("""COMPUTED_VALUE"""),46114) -> 46114 | G2: =IFERROR(__xludf.DUMMYFUNCTION("""COMPUTED_VALUE"""),"B2C") -> B2C | H2: =IFERROR(__xludf.DUMMYFUNCTION("""COMPUTED_VALUE"""),"Jalaj Rawat") -> Jalaj Rawat
A3: =IFERROR(__xludf.DUMMYFUNCTION("""COMPUTED_VALUE"""),2) -> 2 | B3: =IFERROR(__xludf.DUMMYFUNCTION("""COMPUTED_VALUE"""),"Indore City") -> Indore City | C3: =IFERROR(__xludf.DUMMYFUNCTION("""COMPUTED_VALUE"""),"PRIYAL AQUATECH SERVICES") -> PRIYAL AQUATECH SERVICES | D3: =IFERROR(__xludf.DUMMYFUNCTION("""COMPUTED_VALUE"""),1893026504) -> 1893026504 | E3: =IFERROR(__xludf.DUMMYFUNCTION("""COMPUTED_VALUE"""),46114) -> 46114 | G3: =IFERROR(__xludf.DUMMYFUNCTION("""COMPUTED_VALUE"""),"B2C") -> B2C | H3: =IFERROR(__xludf.DUMMYFUNCTION("""COMPUTED_VALUE"""),"Jalaj Rawat") -> Jalaj Rawat
A4: =IFERROR(__xludf.DUMMYFUNCTION("""COMPUTED_VALUE"""),3) -> 3 | B4: =IFERROR(__xludf.DUMMYFUNCTION("""COMPUTED_VALUE"""),"Indore City") -> Indore City | C4: =IFERROR(__xludf.DUMMYFUNCTION("""COMPUTED_VALUE"""),"VARNSHIKA HERBALS PVT LTD") -> VARNSHIKA HERBALS PVT LTD | D4: =IFERROR(__xludf.DUMMYFUNCTION("""COMPUTED_VALUE"""),1149636129) -> 1149636129 | E4: =IFERROR(__xludf.DUMMYFUNCTION("""COMPUTED_VALUE"""),46114) -> 46114 | G4: =IFERROR(__xludf.DUMMYFUNCTION("""COMPUTED_VALUE"""),"B2C") -> B2C | H4: =IFERROR(__xludf.DUMMYFUNCTION("""COMPUTED_VALUE"""),"Rahul Panchal") -> Rahul Panchal
A5: =IFERROR(__xludf.DUMMYFUNCTION("""COMPUTED_VALUE"""),4) -> 4 | B5: =IFERROR(__xludf.DUMMYFUNCTION("""COMPUTED_VALUE"""),"Indore City") -> Indore City | C5: =IFERROR(__xludf.DUMMYFUNCTION("""COMPUTED_VALUE"""),"SANWARIYA HERBALS") -> SANWARIYA HERBALS | D5: =IFERROR(__xludf.DUMMYFUNCTION("""COMPUTED_VALUE"""),1858516980) -> 1858516980 | E5: =IFERROR(__xludf.DUMMYFUNCTION("""COMPUTED_VALUE"""),46119) -> 46119 | G5: =IFERROR(__xludf.DUMMYFUNCTION("""COMPUTED_VALUE"""),"B2C") -> B2C | H5: =IFERROR(__xludf.DUMMYFUNCTION("""COMPUTED_VALUE"""),"Jalaj Rawat") -> Jalaj Rawat
A6: =IFERROR(__xludf.DUMMYFUNCTION("""COMPUTED_VALUE"""),5) -> 5 | B6: =IFERROR(__xludf.DUMMYFUNCTION("""COMPUTED_VALUE"""),"Indore City") -> Indore City | C6: =IFERROR(__xludf.DUMMYFUNCTION("""COMPUTED_VALUE"""),"Bank of India zonal office indore") -> Bank of India zonal office indore | D6: =IFERROR(__xludf.DUMMYFUNCTION("""COMPUTED_VALUE"""),1540291063) -> 1540291063 | E6: =IFERROR(__xludf.DUMMYFUNCTION("""COMPUTED_VALUE"""),46121) -> 46121 | G6: =IFERROR(__xludf.DUMMYFUNCTION("""COMPUTED_VALUE"""),"B2C") -> B2C | H6: =IFERROR(__xludf.DUMMYFUNCTION("""COMPUTED_VALUE"""),"Jalaj Rawat") -> Jalaj Rawat
A7: =IFERROR(__xludf.DUMMYFUNCTION("""COMPUTED_VALUE"""),6) -> 6 | B7: =IFERROR(__xludf.DUMMYFUNCTION("""COMPUTED_VALUE"""),"Indore City") -> Indore City | C7: =IFERROR(__xludf.DUMMYFUNCTION("""COMPUTED_VALUE"""),"SWARAJ COACHING CLASSES") -> SWARAJ COACHING CLASSES | D7: =IFERROR(__xludf.DUMMYFUNCTION("""COMPUTED_VALUE"""),1601260495) -> 1601260495 | E7: =IFERROR(__xludf.DUMMYFUNCTION("""COMPUTED_VALUE"""),46121) -> 46121 | G7: =IFERROR(__xludf.DUMMYFUNCTION("""COMPUTED_VALUE"""),"B2C") -> B2C | H7: =IFERROR(__xludf.DUMMYFUNCTION("""COMPUTED_VALUE"""),"Zuber Ahmed Khan") -> Zuber Ahmed Khan
A8: =IFERROR(__xludf.DUMMYFUNCTION("""COMPUTED_VALUE"""),7) -> 7 | B8: =IFERROR(__xludf.DUMMYFUNCTION("""COMPUTED_VALUE"""),"Indore City") -> Indore City | C8: =IFERROR(__xludf.DUMMYFUNCTION("""COMPUTED_VALUE"""),"MPPKVVCL") -> MPPKVVCL | D8: =IFERROR(__xludf.DUMMYFUNCTION("""COMPUTED_VALUE"""),1955152285) -> 1955152285 | E8: =IFERROR(__xludf.DUMMYFUNCTION("""COMPUTED_VALUE"""),46127) -> 46127 | G8: =IFERROR(__xludf.DUMMYFUNCTION("""COMPUTED_VALUE"""),"B2C") -> B2C | H8: =IFERROR(__xludf.DUMMYFUNCTION("""COMPUTED_VALUE"""),"Rahul Panchal") -> Rahul Panchal
A9: =IFERROR(__xludf.DUMMYFUNCTION("""COMPUTED_VALUE"""),8) -> 8 | B9: =IFERROR(__xludf.DUMMYFUNCTION("""COMPUTED_VALUE"""),"Indore City") -> Indore City | C9: =IFERROR(__xludf.DUMMYFUNCTION("""COMPUTED_VALUE"""),"RSP ENTERPRISES") -> RSP ENTERPRISES | D9: =IFERROR(__xludf.DUMMYFUNCTION("""COMPUTED_VALUE"""),1784698475) -> 1784698475 | E9: =IFERROR(__xludf.DUMMYFUNCTION("""COMPUTED_VALUE"""),46127) -> 46127 | G9: =IFERROR(__xludf.DUMMYFUNCTION("""COMPUTED_VALUE"""),"B2C") -> B2C | H9: =IFERROR(__xludf.DUMMYFUNCTION("""COMPUTED_VALUE"""),"Jalaj Rawat") -> Jalaj Rawat
A10: =IFERROR(__xludf.DUMMYFUNCTION("""COMPUTED_VALUE"""),9) -> 9 | B10: =IFERROR(__xludf.DUMMYFUNCTION("""COMPUTED_VALUE"""),"Indore City") -> Indore City | C10: =IFERROR(__xludf.DUMMYFUNCTION("""COMPUTED_VALUE"""),"SP WORLD SOLUTION") -> SP WORLD SOLUTION | D10: =IFERROR(__xludf.DUMMYFUNCTION("""COMPUTED_VALUE"""),1802814193) -> 1802814193 | E10: =IFERROR(__xludf.DUMMYFUNCTION("""COMPUTED_VALUE"""),46127) -> 46127 | G10: =IFERROR(__xludf.DUMMYFUNCTION("""COMPUTED_VALUE"""),"B2C") -> B2C | H10: =IFERROR(__xludf.DUMMYFUNCTION("""COMPUTED_VALUE"""),"Jalaj Rawat") -> Jalaj Rawat
A11: =IFERROR(__xludf.DUMMYFUNCTION("""COMPUTED_VALUE"""),10) -> 10 | B11: =IFERROR(__xludf.DUMMYFUNCTION("""COMPUTED_VALUE"""),"Indore City") -> Indore City | C11: =IFERROR(__xludf.DUMMYFUNCTION("""COMPUTED_VALUE"""),"ASHU HERBAL") -> ASHU HERBAL | D11: =IFERROR(__xludf.DUMMYFUNCTION("""COMPUTED_VALUE"""),1264378880) -> 1264378880 | E11: =IFERROR(__xludf.DUMMYFUNCTION("""COMPUTED_VALUE"""),46128) -> 46128 | G11: =IFERROR(__xludf.DUMMYFUNCTION("""COMPUTED_VALUE"""),"B2C") -> B2C | H11: =IFERROR(__xludf.DUMMYFUNCTION("""COMPUTED_VALUE"""),"Zuber Ahmed Khan") -> Zuber Ahmed Khan
A12: =IFERROR(__xludf.DUMMYFUNCTION("""COMPUTED_VALUE"""),11) -> 11 | B12: =IFERROR(__xludf.DUMMYFUNCTION("""COMPUTED_VALUE"""),"Indore City") -> Indore City | C12: =IFERROR(__xludf.DUMMYFUNCTION("""COMPUTED_VALUE"""),"JAIN ENTERPRISES") -> JAIN ENTERPRISES | D12: =IFERROR(__xludf.DUMMYFUNCTION("""COMPUTED_VALUE"""),1244430040) -> 1244430040 | E12: =IFERROR(__xludf.DUMMYFUNCTION("""COMPUTED_VALUE"""),46136) -> 46136 | G12: =IFERROR(__xludf.DUMMYFUNCTION("""COMPUTED_VALUE"""),"B2C") -> B2C | H12: =IFERROR(__xludf.DUMMYFUNCTION("""COMPUTED_VALUE"""),"Jalaj Rawat") -> Jalaj Rawat
A13: =IFERROR(__xludf.DUMMYFUNCTION("""COMPUTED_VALUE"""),12) -> 12 | B13: =IFERROR(__xludf.DUMMYFUNCTION("""COMPUTED_VALUE"""),"Indore City") -> Indore City | C13: =IFERROR(__xludf.DUMMYFUNCTION("""COMPUTED_VALUE"""),"LASNARO AGROVET PRIVATE LIMITED") -> LASNARO AGROVET PRIVATE LIMITED | D13: =IFERROR(__xludf.DUMMYFUNCTION("""COMPUTED_VALUE"""),1335697406) -> 1335697406 | E13: =IFERROR(__xludf.DUMMYFUNCTION("""COMPUTED_VALUE"""),46136) -> 46136 | G13: =IFERROR(__xludf.DUMMYFUNCTION("""COMPUTED_VALUE"""),"B2C") -> B2C | H13: =IFERROR(__xludf.DUMMYFUNCTION("""COMPUTED_VALUE"""),"Rahul Panchal") -> Rahul Panchal
A14: =IFERROR(__xludf.DUMMYFUNCTION("""COMPUTED_VALUE"""),13) -> 13 | B14: =IFERROR(__xludf.DUMMYFUNCTION("""COMPUTED_VALUE"""),"Indore City") -> Indore City | C14: =IFERROR(__xludf.DUMMYFUNCTION("""COMPUTED_VALUE"""),"Brain Box") -> Brain Box | D14: =IFERROR(__xludf.DUMMYFUNCTION("""COMPUTED_VALUE"""),1651181890) -> 1651181890 | E14: =IFERROR(__xludf.DUMMYFUNCTION("""COMPUTED_VALUE"""),46121) -> 46121 | G14: =IFERROR(__xludf.DUMMYFUNCTION("""COMPUTED_VALUE"""),"B2C") -> B2C | H14: =IFERROR(__xludf.DUMMYFUNCTION("""COMPUTED_VALUE"""),"Zuber Ahmed Khan") -> Zuber Ahmed Khan
A15: =IFERROR(__xludf.DUMMYFUNCTION("""COMPUTED_VALUE"""),14) -> 14 | B15: =IFERROR(__xludf.DUMMYFUNCTION("""COMPUTED_VALUE"""),"Indore City") -> Indore City | C15: =IFERROR(__xludf.DUMMYFUNCTION("""COMPUTED_VALUE"""),"SPNIWCD RC Indore") -> SPNIWCD RC Indore | D15: =IFERROR(__xludf.DUMMYFUNCTION("""COMPUTED_VALUE"""),1723023500) -> 1723023500 | E15: =IFERROR(__xludf.DUMMYFUNCTION("""COMPUTED_VALUE"""),46136) -> 46136 | G15: =IFERROR(__xludf.DUMMYFUNCTION("""COMPUTED_VALUE"""),"B2C") -> B2C | H15: =IFERROR(__xludf.DUMMYFUNCTION("""COMPUTED_VALUE"""),"Jalaj Rawat") -> Jalaj Rawat
A16: =IFERROR(__xludf.DUMMYFUNCTION("""COMPUTED_VALUE"""),15) -> 15 | B16: =IFERROR(__xludf.DUMMYFUNCTION("""COMPUTED_VALUE"""),"Indore City") -> Indore City | C16: =IFERROR(__xludf.DUMMYFUNCTION("""COMPUTED_VALUE"""),"govt. holkar science college") -> govt. holkar science college | D16: =IFERROR(__xludf.DUMMYFUNCTION("""COMPUTED_VALUE"""),1598560103) -> 1598560103 | E16: =IFERROR(__xludf.DUMMYFUNCTION("""COMPUTED_VALUE"""),46146) -> 46146 | G16: =IFERROR(__xludf.DUMMYFUNCTION("""COMPUTED_VALUE"""),"B2C") -> B2C | H16: =IFERROR(__xludf.DUMMYFUNCTION("""COMPUTED_VALUE"""),"Rahul Panchal") -> Rahul Panchal
A17: =IFERROR(__xludf.DUMMYFUNCTION("""COMPUTED_VALUE"""),16) -> 16 | B17: =IFERROR(__xludf.DUMMYFUNCTION("""COMPUTED_VALUE"""),"Indore City") -> Indore City | C17: =IFERROR(__xludf.DUMMYFUNCTION("""COMPUTED_VALUE"""),"NAVPRAN ENTERPRISES PVT LTD") -> NAVPRAN ENTERPRISES PVT LTD | D17: =IFERROR(__xludf.DUMMYFUNCTION("""COMPUTED_VALUE"""),1751940875) -> 1751940875 | E17: =IFERROR(__xludf.DUMMYFUNCTION("""COMPUTED_VALUE"""),46154) -> 46154 | G17: =IFERROR(__xludf.DUMMYFUNCTION("""COMPUTED_VALUE"""),"B2C") -> B2C | H17: =IFERROR(__xludf.DUMMYFUNCTION("""COMPUTED_VALUE"""),"Jalaj Rawat") -> Jalaj Rawat
A18: =IFERROR(__xludf.DUMMYFUNCTION("""COMPUTED_VALUE"""),17) -> 17 | B18: =IFERROR(__xludf.DUMMYFUNCTION("""COMPUTED_VALUE"""),"Indore City") -> Indore City | C18: =IFERROR(__xludf.DUMMYFUNCTION("""COMPUTED_VALUE"""),"AAHARSUDHI") -> AAHARSUDHI | D18: =IFERROR(__xludf.DUMMYFUNCTION("""COMPUTED_VALUE"""),1404760827) -> 1404760827 | E18: =IFERROR(__xludf.DUMMYFUNCTION("""COMPUTED_VALUE"""),46157) -> 46157 | G18: =IFERROR(__xludf.DUMMYFUNCTION("""COMPUTED_VALUE"""),"B2C") -> B2C | H18: =IFERROR(__xludf.DUMMYFUNCTION("""COMPUTED_VALUE"""),"Jalaj Rawat") -> Jalaj Rawat
A19: =IFERROR(__xludf.DUMMYFUNCTION("""COMPUTED_VALUE"""),18) -> 18 | B19: =IFERROR(__xludf.DUMMYFUNCTION("""COMPUTED_VALUE"""),"Indore City") -> Indore City | C19: =IFERROR(__xludf.DUMMYFUNCTION("""COMPUTED_VALUE"""),"DNHS HEAL THCARE DEVICES PRIVATE LIMITED") -> DNHS HEAL THCARE DEVICES PRIVATE LIMITED | D19: =IFERROR(__xludf.DUMMYFUNCTION("""COMPUTED_VALUE"""),1677646540) -> 1677646540 | E19: =IFERROR(__xludf.DUMMYFUNCTION("""COMPUTED_VALUE"""),46157) -> 46157 | G19: =IFERROR(__xludf.DUMMYFUNCTION("""COMPUTED_VALUE"""),"B2C") -> B2C | H19: =IFERROR(__xludf.DUMMYFUNCTION("""COMPUTED_VALUE"""),"Zuber Ahmed Khan") -> Zuber Ahmed Khan
A20: =IFERROR(__xludf.DUMMYFUNCTION("""COMPUTED_VALUE"""),19) -> 19 | B20: =IFERROR(__xludf.DUMMYFUNCTION("""COMPUTED_VALUE"""),"Indore City") -> Indore City | C20: =IFERROR(__xludf.DUMMYFUNCTION("""COMPUTED_VALUE"""),"RAHI COLLECTION") -> RAHI COLLECTION | D20: =IFERROR(__xludf.DUMMYFUNCTION("""COMPUTED_VALUE"""),1295229907) -> 1295229907 | E20: =IFERROR(__xludf.DUMMYFUNCTION("""COMPUTED_VALUE"""),46157) -> 46157 | G20: =IFERROR(__xludf.DUMMYFUNCTION("""COMPUTED_VALUE"""),"B2C") -> B2C | H20: =IFERROR(__xludf.DUMMYFUNCTION("""COMPUTED_VALUE"""),"Jalaj Rawat") -> Jalaj Rawat
A21: =IFERROR(__xludf.DUMMYFUNCTION("""COMPUTED_VALUE"""),20) -> 20 | B21: =IFERROR(__xludf.DUMMYFUNCTION("""COMPUTED_VALUE"""),"Indore City") -> Indore City | C21: =IFERROR(__xludf.DUMMYFUNCTION("""COMPUTED_VALUE"""),"Superb Apparels") -> Superb Apparels | D21: =IFERROR(__xludf.DUMMYFUNCTION("""COMPUTED_VALUE"""),1900618990) -> 1900618990 | E21: =IFERROR(__xludf.DUMMYFUNCTION("""COMPUTED_VALUE"""),46157) -> 46157 | G21: =IFERROR(__xludf.DUMMYFUNCTION("""COMPUTED_VALUE"""),"B2C") -> B2C | H21: =IFERROR(__xludf.DUMMYFUNCTION("""COMPUTED_VALUE"""),"Jalaj Rawat") -> Jalaj Rawat
A22: =IFERROR(__xludf.DUMMYFUNCTION("""COMPUTED_VALUE"""),21) -> 21 | B22: =IFERROR(__xludf.DUMMYFUNCTION("""COMPUTED_VALUE"""),"Indore City") -> Indore City | C22: =IFERROR(__xludf.DUMMYFUNCTION("""COMPUTED_VALUE"""),"SWASTIKA INVESTMART LIMITED") -> SWASTIKA INVESTMART LIMITED | D22: =IFERROR(__xludf.DUMMYFUNCTION("""COMPUTED_VALUE"""),1995115361) -> 1995115361 | E22: =IFERROR(__xludf.DUMMYFUNCTION("""COMPUTED_VALUE"""),46160) -> 46160 | G22: =IFERROR(__xludf.DUMMYFUNCTION("""COMPUTED_VALUE"""),"B2C") -> B2C | H22: =IFERROR(__xludf.DUMMYFUNCTION("""COMPUTED_VALUE"""),"Zuber Ahmed Khan") -> Zuber Ahmed Khan
A23: =IFERROR(__xludf.DUMMYFUNCTION("""COMPUTED_VALUE"""),22) -> 22 | B23: =IFERROR(__xludf.DUMMYFUNCTION("""COMPUTED_VALUE"""),"Indore City") -> Indore City | C23: =IFERROR(__xludf.DUMMYFUNCTION("""COMPUTED_VALUE"""),"CDTL Indore") -> CDTL Indore | D23: =IFERROR(__xludf.DUMMYFUNCTION("""COMPUTED_VALUE"""),1928644086) -> 1928644086 | E23: =IFERROR(__xludf.DUMMYFUNCTION("""COMPUTED_VALUE"""),46161) -> 46161 | G23: =IFERROR(__xludf.DUMMYFUNCTION("""COMPUTED_VALUE"""),"B2C") -> B2C | H23: =IFERROR(__xludf.DUMMYFUNCTION("""COMPUTED_VALUE"""),"Jalaj Rawat") -> Jalaj Rawat
A24: =IFERROR(__xludf.DUMMYFUNCTION("""COMPUTED_VALUE"""),23) -> 23 | B24: =IFERROR(__xludf.DUMMYFUNCTION("""COMPUTED_VALUE"""),"Indore City") -> Indore City | C24: =IFERROR(__xludf.DUMMYFUNCTION("""COMPUTED_VALUE"""),"ELEGANCE") -> ELEGANCE | D24: =IFERROR(__xludf.DUMMYFUNCTION("""COMPUTED_VALUE"""),1484254269) -> 1484254269 | E24: =IFERROR(__xludf.DUMMYFUNCTION("""COMPUTED_VALUE"""),46169) -> 46169 | G24: =IFERROR(__xludf.DUMMYFUNCTION("""COMPUTED_VALUE"""),"B2C") -> B2C | H24: =IFERROR(__xludf.DUMMYFUNCTION("""COMPUTED_VALUE"""),"Rahul Panchal") -> Rahul Panchal
A25: =IFERROR(__xludf.DUMMYFUNCTION("""COMPUTED_VALUE"""),24) -> 24 | B25: =IFERROR(__xludf.DUMMYFUNCTION("""COMPUTED_VALUE"""),"Indore City") -> Indore City | C25: =IFERROR(__xludf.DUMMYFUNCTION("""COMPUTED_VALUE"""),"Grandeur Ventures International") -> Grandeur Ventures International | D25: =IFERROR(__xludf.DUMMYFUNCTION("""COMPUTED_VALUE"""),1316759247) -> 1316759247 | E25: =IFERROR(__xludf.DUMMYFUNCTION("""COMPUTED_VALUE"""),46169) -> 46169 | G25: =IFERROR(__xludf.DUMMYFUNCTION("""COMPUTED_VALUE"""),"B2C") -> B2C | H25: =IFERROR(__xludf.DUMMYFUNCTION("""COMPUTED_VALUE"""),"Jalaj Rawat") -> Jalaj Rawat
A26: =IFERROR(__xludf.DUMMYFUNCTION("""COMPUTED_VALUE"""),25) -> 25 | B26: =IFERROR(__xludf.DUMMYFUNCTION("""COMPUTED_VALUE"""),"Indore City") -> Indore City | C26: =IFERROR(__xludf.DUMMYFUNCTION("""COMPUTED_VALUE"""),"INDIAN OVERSEAS BANK") -> INDIAN OVERSEAS BANK | D26: =IFERROR(__xludf.DUMMYFUNCTION("""COMPUTED_VALUE"""),1728296339) -> 1728296339 | E26: =IFERROR(__xludf.DUMMYFUNCTION("""COMPUTED_VALUE"""),46169) -> 46169 | G26: =IFERROR(__xludf.DUMMYFUNCTION("""COMPUTED_VALUE"""),"B2C") -> B2C | H26: =IFERROR(__xludf.DUMMYFUNCTION("""COMPUTED_VALUE"""),"Rahul Panchal") -> Rahul Panchal
A27: =IFERROR(__xludf.DUMMYFUNCTION("""COMPUTED_VALUE"""),26) -> 26 | B27: =IFERROR(__xludf.DUMMYFUNCTION("""COMPUTED_VALUE"""),"Indore City") -> Indore City | C27: =IFERROR(__xludf.DUMMYFUNCTION("""COMPUTED_VALUE"""),"LABU INTERNATIONAL") -> LABU INTERNATIONAL | D27: =IFERROR(__xludf.DUMMYFUNCTION("""COMPUTED_VALUE"""),1660828615) -> 1660828615 | E27: =IFERROR(__xludf.DUMMYFUNCTION("""COMPUTED_VALUE"""),46169) -> 46169 | G27: =IFERROR(__xludf.DUMMYFUNCTION("""COMPUTED_VALUE"""),"B2C") -> B2C | H27: =IFERROR(__xludf.DUMMYFUNCTION("""COMPUTED_VALUE"""),"Jalaj Rawat") -> Jalaj Rawat
A28: =IFERROR(__xludf.DUMMYFUNCTION("""COMPUTED_VALUE"""),27) -> 27 | B28: =IFERROR(__xludf.DUMMYFUNCTION("""COMPUTED_VALUE"""),"Indore City") -> Indore City | C28: =IFERROR(__xludf.DUMMYFUNCTION("""COMPUTED_VALUE"""),"SANJEEVANI AYURVEDIC") -> SANJEEVANI AYURVEDIC | D28: =IFERROR(__xludf.DUMMYFUNCTION("""COMPUTED_VALUE"""),1132126422) -> 1132126422 | E28: =IFERROR(__xludf.DUMMYFUNCTION("""COMPUTED_VALUE"""),46169) -> 46169 | G28: =IFERROR(__xludf.DUMMYFUNCTION("""COMPUTED_VALUE"""),"B2C") -> B2C | H28: =IFERROR(__xludf.DUMMYFUNCTION("""COMPUTED_VALUE"""),"Rahul Panchal") -> Rahul Panchal
A29: =IFERROR(__xludf.DUMMYFUNCTION("""COMPUTED_VALUE"""),28) -> 28 | B29: =IFERROR(__xludf.DUMMYFUNCTION("""COMPUTED_VALUE"""),"Indore City") -> Indore City | C29: =IFERROR(__xludf.DUMMYFUNCTION("""COMPUTED_VALUE"""),"STATE BANK OF INDIA HIGH COURT BRANCH") -> STATE BANK OF INDIA HIGH COURT BRANCH | D29: =IFERROR(__xludf.DUMMYFUNCTION("""COMPUTED_VALUE"""),1838482754) -> 1838482754 | E29: =IFERROR(__xludf.DUMMYFUNCTION("""COMPUTED_VALUE"""),46169) -> 46169 | G29: =IFERROR(__xludf.DUMMYFUNCTION("""COMPUTED_VALUE"""),"B2C") -> B2C | H29: =IFERROR(__xludf.DUMMYFUNCTION("""COMPUTED_VALUE"""),"Zuber Ahmed Khan") -> Zuber Ahmed Khan
A30: =IFERROR(__xludf.DUMMYFUNCTION("""COMPUTED_VALUE"""),29) -> 29 | B30: =IFERROR(__xludf.DUMMYFUNCTION("""COMPUTED_VALUE"""),"Indore City") -> Indore City | C30: =IFERROR(__xludf.DUMMYFUNCTION("""COMPUTED_VALUE"""),"Union Bank Of India Regal Square") -> Union Bank Of India Regal Square | D30: =IFERROR(__xludf.DUMMYFUNCTION("""COMPUTED_VALUE"""),1329301695) -> 1329301695 | E30: =IFERROR(__xludf.DUMMYFUNCTION("""COMPUTED_VALUE"""),46169) -> 46169 | G30: =IFERROR(__xludf.DUMMYFUNCTION("""COMPUTED_VALUE"""),"B2C") -> B2C | H30: =IFERROR(__xludf.DUMMYFUNCTION("""COMPUTED_VALUE"""),"Jalaj Rawat") -> Jalaj Rawat
A31: =IFERROR(__xludf.DUMMYFUNCTION("""COMPUTED_VALUE"""),30) -> 30 | B31: =IFERROR(__xludf.DUMMYFUNCTION("""COMPUTED_VALUE"""),"Indore City") -> Indore City | C31: =IFERROR(__xludf.DUMMYFUNCTION("""COMPUTED_VALUE"""),"Indusind General Insurance Company Ltd") -> Indusind General Insurance Company Ltd | D31: =IFERROR(__xludf.DUMMYFUNCTION("""COMPUTED_VALUE"""),3000009588) -> 3000009588 | E31: =IFERROR(__xludf.DUMMYFUNCTION("""COMPUTED_VALUE"""),46174) -> 46174 | G31: =IFERROR(__xludf.DUMMYFUNCTION("""COMPUTED_VALUE"""),"B2C") -> B2C | H31: =IFERROR(__xludf.DUMMYFUNCTION("""COMPUTED_VALUE"""),"Jalaj Rawat") -> Jalaj Rawat
A32: =IFERROR(__xludf.DUMMYFUNCTION("""COMPUTED_VALUE"""),31) -> 31 | B32: =IFERROR(__xludf.DUMMYFUNCTION("""COMPUTED_VALUE"""),"Indore City") -> Indore City | C32: =IFERROR(__xludf.DUMMYFUNCTION("""COMPUTED_VALUE"""),"SIPL DATA SERVICES") -> SIPL DATA SERVICES | D32: =IFERROR(__xludf.DUMMYFUNCTION("""COMPUTED_VALUE"""),1804236062) -> 1804236062 | E32: =IFERROR(__xludf.DUMMYFUNCTION("""COMPUTED_VALUE"""),46174) -> 46174 | G32: =IFERROR(__xludf.DUMMYFUNCTION("""COMPUTED_VALUE"""),"B2C") -> B2C | H32: =IFERROR(__xludf.DUMMYFUNCTION("""COMPUTED_VALUE"""),"Jalaj Rawat") -> Jalaj Rawat
A33: =IFERROR(__xludf.DUMMYFUNCTION("""COMPUTED_VALUE"""),32) -> 32 | B33: =IFERROR(__xludf.DUMMYFUNCTION("""COMPUTED_VALUE"""),"Indore City") -> Indore City | C33: =IFERROR(__xludf.DUMMYFUNCTION("""COMPUTED_VALUE"""),"National insurance co. Ltd. IRO") -> National insurance co. Ltd. IRO | D33: =IFERROR(__xludf.DUMMYFUNCTION("""COMPUTED_VALUE"""),1161465239) -> 1161465239 | E33: =IFERROR(__xludf.DUMMYFUNCTION("""COMPUTED_VALUE"""),46176) -> 46176 | G33: =IFERROR(__xludf.DUMMYFUNCTION("""COMPUTED_VALUE"""),"B2C") -> B2C | H33: =IFERROR(__xludf.DUMMYFUNCTION("""COMPUTED_VALUE"""),"Jalaj Rawat") -> Jalaj Rawat
A34: =IFERROR(__xludf.DUMMYFUNCTION("""COMPUTED_VALUE"""),33) -> 33 | B34: =IFERROR(__xludf.DUMMYFUNCTION("""COMPUTED_VALUE"""),"Indore City") -> Indore City | C34: =IFERROR(__xludf.DUMMYFUNCTION("""COMPUTED_VALUE"""),"FIT FOR MAN") -> FIT FOR MAN | D34: =IFERROR(__xludf.DUMMYFUNCTION("""COMPUTED_VALUE"""),1533129385) -> 1533129385 | E34: =IFERROR(__xludf.DUMMYFUNCTION("""COMPUTED_VALUE"""),46182) -> 46182 | G34: =IFERROR(__xludf.DUMMYFUNCTION("""COMPUTED_VALUE"""),"B2C") -> B2C | H34: =IFERROR(__xludf.DUMMYFUNCTION("""COMPUTED_VALUE"""),"Zuber Ahmed Khan") -> Zuber Ahmed Khan
A35: =IFERROR(__xludf.DUMMYFUNCTION("""COMPUTED_VALUE"""),34) -> 34 | B35: =IFERROR(__xludf.DUMMYFUNCTION("""COMPUTED_VALUE"""),"Indore City") -> Indore City | C35: =IFERROR(__xludf.DUMMYFUNCTION("""COMPUTED_VALUE"""),"LAKSHYA OVERSEAS EDUCATION") -> LAKSHYA OVERSEAS EDUCATION | D35: =IFERROR(__xludf.DUMMYFUNCTION("""COMPUTED_VALUE"""),1129271649) -> 1129271649 | E35: =IFERROR(__xludf.DUMMYFUNCTION("""COMPUTED_VALUE"""),46182) -> 46182 | G35: =IFERROR(__xludf.DUMMYFUNCTION("""COMPUTED_VALUE"""),"B2C") -> B2C | H35: =IFERROR(__xludf.DUMMYFUNCTION("""COMPUTED_VALUE"""),"Rahul Panchal") -> Rahul Panchal
A36: =IFERROR(__xludf.DUMMYFUNCTION("""COMPUTED_VALUE"""),35) -> 35 | B36: =IFERROR(__xludf.DUMMYFUNCTION("""COMPUTED_VALUE"""),"Indore City") -> Indore City | C36: =IFERROR(__xludf.DUMMYFUNCTION("""COMPUTED_VALUE"""),"Patanjali Foods Limited") -> Patanjali Foods Limited | D36: =IFERROR(__xludf.DUMMYFUNCTION("""COMPUTED_VALUE"""),1422857286) -> 1422857286 | E36: =IFERROR(__xludf.DUMMYFUNCTION("""COMPUTED_VALUE"""),46182) -> 46182 | G36: =IFERROR(__xludf.DUMMYFUNCTION("""COMPUTED_VALUE"""),"B2C") -> B2C | H36: =IFERROR(__xludf.DUMMYFUNCTION("""COMPUTED_VALUE"""),"Jalaj Rawat") -> Jalaj Rawat
A37: =IFERROR(__xludf.DUMMYFUNCTION("""COMPUTED_VALUE"""),36) -> 36 | B37: =IFERROR(__xludf.DUMMYFUNCTION("""COMPUTED_VALUE"""),"Indore City") -> Indore City | C37: =IFERROR(__xludf.DUMMYFUNCTION("""COMPUTED_VALUE"""),"Union Bank of India ARB Branch") -> Union Bank of India ARB Branch | D37: =IFERROR(__xludf.DUMMYFUNCTION("""COMPUTED_VALUE"""),1943080486) -> 1943080486 | E37: =IFERROR(__xludf.DUMMYFUNCTION("""COMPUTED_VALUE"""),46182) -> 46182 | G37: =IFERROR(__xludf.DUMMYFUNCTION("""COMPUTED_VALUE"""),"B2C") -> B2C | H37: =IFERROR(__xludf.DUMMYFUNCTION("""COMPUTED_VALUE"""),"Zuber Ahmed Khan") -> Zuber Ahmed Khan
A38: =IFERROR(__xludf.DUMMYFUNCTION("""COMPUTED_VALUE"""),37) -> 37 | B38: =IFERROR(__xludf.DUMMYFUNCTION("""COMPUTED_VALUE"""),"Indore City") -> Indore City | C38: =IFERROR(__xludf.DUMMYFUNCTION("""COMPUTED_VALUE"""),"VATYA THE LABEL") -> VATYA THE LABEL | D38: =IFERROR(__xludf.DUMMYFUNCTION("""COMPUTED_VALUE"""),1188407437) -> 1188407437 | E38: =IFERROR(__xludf.DUMMYFUNCTION("""COMPUTED_VALUE"""),46182) -> 46182 | G38: =IFERROR(__xludf.DUMMYFUNCTION("""COMPUTED_VALUE"""),"B2C") -> B2C | H38: =IFERROR(__xludf.DUMMYFUNCTION("""COMPUTED_VALUE"""),"Rahul Panchal") -> Rahul Panchal
A39: =IFERROR(__xludf.DUMMYFUNCTION("""COMPUTED_VALUE"""),38) -> 38 | B39: =IFERROR(__xludf.DUMMYFUNCTION("""COMPUTED_VALUE"""),"Indore City") -> Indore City | C39: =IFERROR(__xludf.DUMMYFUNCTION("""COMPUTED_VALUE"""),"MUKUL LEARNING SYSTEMS LLP") -> MUKUL LEARNING SYSTEMS LLP | D39: =IFERROR(__xludf.DUMMYFUNCTION("""COMPUTED_VALUE"""),1808596663) -> 1808596663 | E39: =IFERROR(__xludf.DUMMYFUNCTION("""COMPUTED_VALUE"""),46195) -> 46195 | G39: =IFERROR(__xludf.DUMMYFUNCTION("""COMPUTED_VALUE"""),"B2C") -> B2C | H39: =IFERROR(__xludf.DUMMYFUNCTION("""COMPUTED_VALUE"""),"Zuber Ahmed Khan") -> Zuber Ahmed Khan
A40: =IFERROR(__xludf.DUMMYFUNCTION("""COMPUTED_VALUE"""),39) -> 39 | B40: =IFERROR(__xludf.DUMMYFUNCTION("""COMPUTED_VALUE"""),"Indore City") -> Indore City | C40: =IFERROR(__xludf.DUMMYFUNCTION("""COMPUTED_VALUE"""),"The Easy Shopping") -> The Easy Shopping | D40: =IFERROR(__xludf.DUMMYFUNCTION("""COMPUTED_VALUE"""),1583054640) -> 1583054640 | E40: =IFERROR(__xludf.DUMMYFUNCTION("""COMPUTED_VALUE"""),46195) -> 46195 | G40: =IFERROR(__xludf.DUMMYFUNCTION("""COMPUTED_VALUE"""),"B2C") -> B2C | H40: =IFERROR(__xludf.DUMMYFUNCTION("""COMPUTED_VALUE"""),"Rahul Panchal") -> Rahul Panchal
...

Sheet Indore City
F2: From Date 01.04.2026 to 31.08.2026
B3: S.No. | C3: Division | D3: Name of Customer | E3: Customer ID | F3: Date of Onboarding | G3: Product Type | H3: B2B Or B2C | I3: Name of ME Who Onboarded | J3: Customer Type Advance/ BNPL
B4: 1 | C4: Indore City | D4: DRASHTI ENTERPRISES | E4: 1504860613 | F4: 46114 | H4: B2C | I4: Jalaj Rawat
B5: 2 | C5: Indore City | D5: PRIYAL AQUATECH SERVICES | E5: 1893026504 | F5: 46114 | H5: B2C | I5: Jalaj Rawat
B6: 3 | C6: Indore City | D6: VARNSHIKA HERBALS PVT LTD | E6: 1149636129 | F6: 46114 | H6: B2C | I6: Rahul Panchal
B7: 4 | C7: Indore City | D7: SANWARIYA HERBALS | E7: 1858516980 | F7: 46119 | H7: B2C | I7: Jalaj Rawat
B8: 5 | C8: Indore City | D8: Bank of India zonal office indore | E8: 1540291063 | F8: 46121 | H8: B2C | I8: Jalaj Rawat
B9: 6 | C9: Indore City | D9: SWARAJ COACHING CLASSES | E9: 1601260495 | F9: 46121 | H9: B2C | I9: Zuber Ahmed Khan
B10: 7 | C10: Indore City | D10: MPPKVVCL | E10: 1955152285 | F10: 46127 | H10: B2C | I10: Rahul Panchal
B11: 8 | C11: Indore City | D11: RSP ENTERPRISES | E11: 1784698475 | F11: 46127 | H11: B2C | I11: Jalaj Rawat
B12: 9 | C12: Indore City | D12: SP WORLD SOLUTION | E12: 1802814193 | F12: 46127 | H12: B2C | I12: Jalaj Rawat
B13: 10 | C13: Indore City | D13: ASHU HERBAL | E13: 1264378880 | F13: 46128 | H13: B2C | I13: Zuber Ahmed Khan
B14: 11 | C14: Indore City | D14: JAIN ENTERPRISES | E14: 1244430040 | F14: 46136 | H14: B2C | I14: Jalaj Rawat
B15: 12 | C15: Indore City | D15: LASNARO AGROVET PRIVATE LIMITED | E15: 1335697406 | F15: 46136 | H15: B2C | I15: Rahul Panchal
... B147: 144 | C147: Indore City | D147: SDJ ENTERPRISES | E147: 1834308501 | F147: 46294 | H147: B2C | I147: Jalaj Rawat

Sheet Indore MFL
F2: From Date 01.04.2026 to 31.08.2026
B3: S.No. | C3: Division | D3: Name of Customer | E3: Customer ID | F3: Date of Onboarding | G3: Product Type | H3: B2B Or B2C | I3: Name of ME Who Onboarded | J3: Customer Type Advance/ BNPL
B4: 1 | C4: Indore MFL | D4: SBI AMCC DEWAS | E4: 1143151756 | F4: 46251 | G4: LETTERS | H4: B2C | I4: SANTOSH VERMA | J4: BNPL
B5: 2 | C5: Indore MFL | D5: GURUKRIPA FOODS | E5: 1724127341 | F5: 46248 | G5: FMCG | H5: B2C | I5: BRIJESH SHRIVAS | J5: ADVANCE
B6: 3 | C6: Indore MFL | D6: KASHISH SAREE | E6: 1176938537 | F6: 46246 | G6: FASHION | H6: B2C | I6: SANTOSH VERMA | J6: ADVANCE
B7: 4 | C7: Indore MFL | D7: SA HERBAL BIOACTIVE LLP | E7: 1646616392 | F7: 46246 | G7: HERBVAL PRODUCTS | H7: B2C | I7: BRIJESH SHRIVAS | J7: ADVANCE
B8: 5 | C8: Indore MFL | D8: BHUMI AGRO INDUSTRIES | E8: 1761937114 | F8: 46239 | G8: LETTERS | H8: B2C | I8: SANTOSH VERMA | J8: ADVANCE
B9: 6 | C9: Indore MFL | D9: CENTRAL BANK OF INDIA | E9: 1512057439 | F9: 46232 | G9: HERBVAL PRODUCTS | H9: B2C | I9: BRIJESH SHRIVAS | J9: BNPL
B10: 7 | C10: Indore MFL | D10: BHUMI AGRO INDUSTRIES | E10: 1761937114 | F10: 46226 | G10: MEDICINES | H10: B2C | I10: SANTOSH VERMA | J10: ADVANCE
B11: 8 | C11: Indore MFL | D11: GOVIRA | E11: 1495342035 | F11: 46221 | G11: LETTERS | H11: B2C | I11: SANTOSH VERMA | J11: ADVANCE
B12: 9 | C12: Indore MFL | D12: state bank of india | E12: 1638295373 | F12: 46220 | G12: LETTERS | H12: B2C | I12: BRIJESH SHRIVAS | J12: BNPL
B13: 10 | C13: Indore MFL | D13: INNOVATIVE ENTERPRISES | E13: 1819752277 | F13: 46203 | G13: SPORTS PRODUCTS | H13: B2C | I13: SANTOSH VERMA | J13: ADVANCE
B14: 11 | C14: Indore MFL | D14: Rahul Khichi | E14: 1304572708 | F14: 46197 | G14: MACHINE GOODS | H14: B2C | I14: SANTOSH VERMA | J14: ADVANCE
B15: 12 | C15: Indore MFL | D15: LIC OF INDIA | E15: 1926099029 | F15: 46192 | G15: LETTERS | H15: B2C | I15: BRIJESH SHRIVAS | J15: BNPL
... B30: 27 | C30: Indore MFL | D30: IPPB Dewas | E30: 1973617996 | F30: 46266 | G30: LETTERS | H30: B2C | I30: SANTOSH VERMA | J30: BNPL

Sheet Khandwa
F2: From Date 01.04.2026 to 31.08.2026
B3: S.No. | C3: Division | D3: Name of Customer | E3: Customer ID | F3: Date of Onboarding | G3: Product Type | H3: B2B Or B2C | I3: Name of ME Who Onboarded | J3: Customer Type Advance/ BNPL
B4: 1 | C4: Khandwa | D4: PIONEER HANDLOOM | E4: 1599830445 | F4: 24.08.2026 | G4: Speed Post Parcel Domestic | H4: B2C | I4: VINEET PATEL | J4: ADVANCE
B5: 2 | C5: Khandwa | D5: SHIVRAM BILLORE | E5: 1433891952 | F5: 21.08.2026 | G5: Speed Post Parcel Domestic | H5: B2C | I5: VINEET PATEL | J5: ADVANCE
B6: 3 | C6: Khandwa | D6: BHAGYASHREE AGRAWAL | E6: 1147531131 | F6: 21.08.2026 | G6: Indiapost Parcel Contractual | H6: B2C | I6: junaid khan | J6: ADVANCE
B7: 4 | C7: Khandwa | D7: New Kanpur Chappal Sale | E7: 1438989417 | F7: 20.08.2026 | G7: Indiapost Parcel Contractual | H7: B2C | I7: VINEET PATEL | J7: ADVANCE
B8: 5 | C8: Khandwa | D8: AKHTAR KHAN | E8: 1896217385 | F8: 17.08.2026 | G8: Indiapost Parcel Contractual | H8: B2C | I8: junaid khan | J8: ADVANCE
B9: 6 | C9: Khandwa | D9: YASHWANT MANGOLIYA | E9: 1582492512 | F9: 17.08.2026 | G9: Indiapost Parcel Contractual | H9: B2C | I9: VINEET PATEL | J9: ADVANCE
B10: 7 | C10: Khandwa | D10: MISS CHORCHET | E10: 1000058530 | F10: 17.08.2026 | G10: Indiapost Parcel Contractual | H10: B2C | I10: Sunil bhojwani | J10: ADVANCE
B11: 8 | C11: Khandwa | D11: MAHAK ASWANI | E11: 1509137621 | F11: 17.08.2026 | G11: Indiapost Parcel Contractual | H11: B2C | I11: junaid khan | J11: ADVANCE
B12: 9 | C12: Khandwa | D12: Khushi Shoes house | E12: 1454741637 | F12: 17.08.2026 | G12: Speed Post Parcel Domestic | H12: B2C | I12: VINEET PATEL | J12: ADVANCE
B13: 10 | C13: Khandwa | D13: AALI QADAR CLOTH STORES AND GENTS TAILORS | E13: 1849113146 | F13: 12.08.2026 | G13: Speed Post Parcel Domestic | H13: B2C | I13: Sunil bhojwani | J13: ADVANCE
B14: 11 | C14: Khandwa | D14: JITENDRA SISODIYA | E14: 1275942889 | F14: 12.08.2026 | G14: Speed Post Parcel Domestic | H14: B2C | I14: VINEET PATEL | J14: ADVANCE
B15: 12 | C15: Khandwa | D15: S M VILLAGE ENTERPRISE | E15: 1000058717 | F15: 17.08.2026 | G15: Indiapost Parcel Contractual | H15: B2C | I15: VINEET PATEL | J15: ADVANCE
... B64: 61 | C64: Khandwa | D64: SANJIVANI | E64: 1102887727 | F64: 08.09.2026 | G64: Speed Post Parcel Domestic | H64: B2C | I64: junaid khan | J64: ADVANCE
B65: 62 | C65: Khandwa | D65: DIDI NIGHT WEAR | E65: 1671108458 | F65: 08.09.2026 | G65: Indiapost Parcel Contractual | H65: B2C | J65: ADVANCE
B66: 63 | C66: Khandwa | D66: AYAJ KHAN | E66: 1621303953 | F66: 08.09.2026 | G66: Speed Post Parcel Domestic | H66: B2C | I66: sunil bhojwani | J66: ADVANCE
B67: 64 | C67: Khandwa | D67: AHSAAN ZAHEER QURESHI | E67: 1554947937 | F67: 08.09.2026 | G67: Speed Post Parcel Domestic | H67: B2C | J67: ADVANCE
B68: 65 | C68: Khandwa | D68: SHYAM SPARES | E68: 1916717972 | F68: 07.09.2026 | G68: Indiapost Parcel Contractual | H68: B2C | I68: sunil bhojwani | J68: ADVANCE
B69: 66 | C69: Khandwa | D69: Sanjay Gulya | E69: 1599377003 | F69: 07.09.2026 | G69: Speed Post Parcel Domestic | H69: B2C | I69: Vineet Patel | J69: ADVANCE
B70: 67 | C70: Khandwa | D70: Pankaj kewat | E70: 1311051856 | F70: 07.09.2026 | G70: Speed Post Parcel Domestic | H70: B2C | I70: vineet patel | J70: ADVANCE
B71: 68 | C71: Khandwa | D71: MISHRILAL VERMA | E71: 1707389443 | F71: 03.09.2026 | G71: Speed Post Parcel Domestic | H71: B2C | I71: vineet patel | J71: ADVANCE
B72: 69 | C72: Khandwa | D72: NAVKAR SAREE EMPORIUM | E72: 1369280565 | F72: 03.09.2026 | G72: Speed Post Parcel Domestic | H72: B2C | I72: santosh rathore | J72: ADVANCE
B73: 70 | C73: Khandwa | D73: NARENDRA JAISWAL | E73: 1408974164 | F73: 03.09.2026 | G73: Speed Post Parcel Domestic | H73: B2C | J73: ADVANCE
B74: 71 | C74: Khandwa | D74: RAVINDRA VERMA | E74: 1787286135 | F74: 03.09.2026 | G74: Speed Post Parcel Domestic | H74: B2C | I74: vineet patel | J74: ADVANCE
B75: 72 | C75: Khandwa | D75: SHIV NARMADESHWAR SHIVLING | E75: 1670881656 | F75: 03.09.2026 | G75: Speed Post Parcel Domestic | H75: B2C | I75: vineet patel | J75: ADVANCE
B76: 73 | C76: Khandwa | D76: Rahul | E76: 1820439245 | F76: 03.09.2026 | G76: Speed Post Parcel Domestic | H76: B2C | I76: vineet Patel | J76: ADVANCE
B77: 74 | C77: Khandwa | D77: SANJAY VERMA | E77: 1676340146 | F77: 03.09.2026 | G77: Speed Post Parcel Domestic | H77: B2C | J77: ADVANCE

Sheet Mandsaur
F2: From Date 01.04.2026 to 31.08.2026
B3: S.No. | C3: Division | D3: Name of Customer | E3: Customer ID | F3: Date of Onboarding | G3: Product Type | H3: B2B Or B2C | I3: Name of ME Who Onboarded | J3: Customer Type Advance/ BNPL
B4: 1 | C4: Mandsaur | D4: THE GLOBUS SHOES | E4: 1608065160 | F4: 46121 | H4: B2C | I4: Shri Yash Mittal | J4: Advance
B5: 2 | C5: Mandsaur | D5: shree shyam agro international | E5: 1750186689 | F5: 46125 | H5: B2C | I5: Shri Yash Mittal | J5: Advance
B6: 3 | C6: Mandsaur | D6: JAI AMBE AGRO | E6: 1109522542 | F6: 46137 | H6: B2C | I6: Shri Yash Mittal | J6: Advance
B7: 4 | C7: Mandsaur | D7: D COLLECTION | E7: 1811297002 | F7: 46141 | H7: B2C | I7: Shri Yash Mittal | J7: Advance
B8: 5 | C8: Mandsaur | D8: BE NONSENSE | E8: 1232594386 | F8: 46155 | H8: B2C | I8: Shri Yash Mittal | J8: Advance
B9: 6 | C9: Mandsaur | D9: AKSHAY CREDIT COOPERATIVE SOCIETY LIMITED | E9: 1487288297 | F9: 46149 | H9: B2C | I9: Shri Vishal Soni | J9: Advance
B10: 7 | C10: Mandsaur | D10: MERY SLATE PEN WORKS | E10: 1676311014 | F10: 46163 | H10: B2C | I10: Shri Vishal Soni | J10: Advance
B11: 8 | C11: Mandsaur | D11: CENTRAL BANK OF INIDA MANDSAUR BRANCH | E11: 1851294619 | F11: 46163 | H11: B2C | I11: Shri Vishal Soni | J11: BNPL
B12: 9 | C12: Mandsaur | D12: ARHAM TRADING COMPANY | E12: 1499665635 | F12: 46163 | H12: B2C | I12: Shri Yash Mittal | J12: Advance
B13: 10 | C13: Mandsaur | D13: INDIAN OVERSEAS BANK | E13: 1992494624 | F13: 46167 | H13: B2C | I13: Shri Yash Mittal | J13: BNPL
B14: 11 | C14: Mandsaur | D14: PANKAJ PATIDAR | E14: 1126866508 | F14: 46171 | H14: B2C | I14: Shri Yash Mittal | J14: Advance
B15: 12 | C15: Mandsaur | D15: PUNJAB NATIONAL BANK | E15: 1418823332 | F15: 46196 | H15: B2C | I15: Shri Yash Mittal | J15: BNPL
... B86: 83 | C86: Mandsaur | D86: Ajay Kumar Sharma | E86: 1737733673 | F86: 46261 | H86: B2C | I86: Shri Yash Mittal | J86: Advance
B87: 84 | C87: Mandsaur | D87: Babji Trading | E87: 1668644900 | F87: 46266 | H87: B2C | J87: Advance
B88: 85 | C88: Mandsaur | D88: Siya Herbal Product | E88: 1186673833 | F88: 46266 | H88: B2C | J88: Advance
B89: 86 | C89: Mandsaur | D89: BHAGIRATH ORGANICS | E89: 1273897653 | F89: 46266 | H89: B2C | J89: Advance
B90: 87 | C90: Mandsaur | D90: matchline electronics | E90: 1128097368 | F90: 46266 | H90: B2C | J90: Advance
B91: 88 | C91: Mandsaur | D91: Sealwell Neemuch | E91: 1176831301 | F91: 46267 | H91: B2C | J91: Advance
B92: 89 | C92: Mandsaur | D92: Pm shri kendriya vidyalaya crpf Neemuch | E92: 1109730268 | F92: 46268 | H92: B2C | I92: Shri Yash Mittal | J92: BNPL
B93: 90 | C93: Mandsaur | D93: POEMS | E93: 1796374199 | F93: 46276 | H93: B2C | I93: Shri Vishal Soni | J93: Advance
B94: 91 | C94: Mandsaur | D94: SHREE SURBHI DHOOP EVAM VEDLAKSHANA GOMATA KA DESHI GHEE | E94: 1567414215 | F94: 46276 | H94: B2C | J94: Advance
B95: 92 | C95: Mandsaur | D95: GULF TOURS AND TRAVELS | E95: 1753922895 | F95: 46280 | H95: B2C | J95: Advance
B96: 93 | C96: Mandsaur | D96: VIRAT SLATE PENCIL | E96: 1242583964 | F96: 46280 | H96: B2C | I96: Shri Vishal Soni | J96: Advance
B97: 94 | C97: Mandsaur | D97: SHUBHAM SAREE CENTER | E97: 1714059911 | F97: 46280 | H97: B2C | J97: Advance
B98: 95 | C98: Mandsaur | D98: THE GOLD FABRICS | E98: 1722386015 | F98: 46280 | H98: B2C | J98: Advance
B99: 96 | C99: Mandsaur | D99: Shree shyam agro international | E99: 1750186689 | F99: 46282 | H99: B2C | J99: Advance
B100: 97 | C100: Mandsaur | D100: Ajay trading company | E100: 1839454215 | F100: 46284 | H100: B2C | I100: Shri Yash Mittal | J100: Advance
B101: 98 | C101: Mandsaur | D101: SBI Khadawada | E101: 1575445425 | F101: 46286 | H101: B2C | I101: Shri Vishal Soni | J101: BNPL
B102: 99 | C102: Mandsaur | D102: Central Bank of India Shamgarh | E102: 1198278689 | F102: 46286 | H102: B2C | I102: Shri Vishal Soni | J102: BNPL
B103: 100 | C103: Mandsaur | D103: Kanha Collection | E103: 1270346341 | F103: 46286 | H103: B2C | I103: Shri Vishal Soni | J103: Advance
B104: 101 | C104: Mandsaur | D104: Vinod tailor | E104: 1884869881 | F104: 46293 | H104: B2C | I104: Shri Yash Mittal | J104: Advance
B105: 102 | C105: Mandsaur | D105: NEEMUCH SPICES LLP | E105: 1901963132 | F105: 46293 | H105: B2C | I105: Shri Yash Mittal | J105: Advance

Sheet Ratlam
F2: From Date 01.04.2026 to 31.08.2026
B3: S.No. | C3: Division | D3: Name of Customer | E3: Customer ID | F3: Date of Onboarding | G3: Product Type | H3: B2B Or B2C | I3: Name of ME Who Onboarded | J3: Customer Type Advance/ BNPL
B4: 1 | C4: Ratlam | D4: Bank of Baroda jaora branch | E4: 1389789531 | F4: 46205 | G4: Speed Post Document | H4: B2C | I4: Abhishek Malviye | J4: BNPL
B5: 2 | C5: Ratlam | D5: DIVINE FEMME | E5: 1162813943 | F5: 46241 | G5: India Post Parcel Contractual | H5: B2C | I5: Abhishek Malviye | J5: Advance
B6: 3 | C6: Ratlam | D6: Kashi Saree | E6: 1300401626 | F6: 46216 | G6: India Post Parcel Contractual | H6: B2C | I6: Abhishek Malviye | J6: Advance
B7: 4 | C7: Ratlam | D7: Jay Dhakad | E7: 1239000513 | F7: 21.05.2026 | G7: India Post Parcel Contractual | H7: B2C | I7: Abhishek Malviye | J7: Advance
B8: 5 | C8: Ratlam | D8: vithalesh sarees | E8: 1196273906 | F8: 18.08.2026 | G8: India Post Parcel Contractual | H8: B2C | I8: Abhishek Malviye | J8: Advance
B9: 6 | C9: Ratlam | D9: Bank of India Krishi Upaj Mandi | E9: 1693473047 | F9: 04.05.2026 | G9: India Post Parcel Contractual | H9: B2C | I9: Ayush Gupta | J9: Advance
B10: 7 | C10: Ratlam | D10: Rang Varsha Sarees | E10: 1318726462 | F10: 29.05.2026 | G10: India Post Parcel Contractual | H10: B2C | I10: Ayush Gupta | J10: Advance
B11: 8 | C11: Ratlam | D11: SBI Rajwada Chowk | E11: 1170048154 | F11: 46252 | G11: Speed Post Document | H11: B2C | I11: Kavita Bhuriya | J11: BNPL
B12: 9 | C12: Ratlam | D12: HDFC BANK JHABUA BRANCH | E12: 1910649609 | F12: 11.06.2026 | G12: Speed Post Document | H12: B2C | I12: Kavita Bhuriya | J12: BNPL
B13: 10 | C13: Ratlam | D13: Divy Narayan Soni | E13: 1254769708 | F13: 21.05.2026 | G13: Speed Post Parcel Contractual | H13: B2B | I13: Kunal Baurasi | J13: Advance
B14: 11 | C14: Ratlam | D14: PANCHAL HOTELWARE AND MACHINARY Lohar road Ratlam | E14: 1241371047 | F14: 16.07.2026 | G14: India Post Parcel Contractual | H14: B2C | I14: Kunal Baurasi | J14: Advance
B15: 12 | C15: Ratlam | D15: Puneet Enterprises | E15: 1351719501 | F15: 25.04.2026 | G15: India Post Parcel Contractual | H15: B2B | I15: Ayush Gupta | J15: Advance
B16: 13 | C16: Ratlam | D16: Sai Services | E16: 1714557030 | F16: 25.06.2026 | G16: India Post Parcel Contractual | H16: B2C | I16: Kunal Baurasi | J16: Advance
B17: 14 | C17: Ratlam | D17: SINDAL AND COMPANY | E17: 1604629625 | F17: 15.05.2026 | G17: India Post Parcel Contractual | H17: B2C | I17: Kunal Baurasi | J17: Advance
B18: 15 | C18: Ratlam | D18: Arihant Imitation | E18: 1444165342 | F18: 18.08.2026 | G18: India Post Parcel Contractual | H18: B2C | I18: Surendra Singh | J18: Advance
B19: 16 | C19: Ratlam | D19: CHETNA TAILOR | E19: 1630516103 | F19: 29.07.2026 | G19: India Post Parcel Contractual | H19: B2C | I19: Ayush Gupta | J19: Advance
B20: 17 | C20: Ratlam | D20: HARDIK BARMECHA | E20: 1908960328 | F20: 46241 | G20: India Post Parcel Contractual | H20: B2C | I20: Surendra Singh | J20: Advance
B21: 18 | C21: Ratlam | D21: MANMEET SAREES | E21: 1225279034 | F21: 46241 | G21: India Post Parcel Contractual | H21: B2C | I21: Surendra Singh | J21: Advance
B22: 19 | C22: Ratlam | D22: NAKODA NX Ratlam | E22: 1468276742 | F22: 46219 | G22: India Post Parcel Contractual | H22: B2C | I22: Surendra Singh | J22: Advance
B23: 20 | C23: Ratlam | D23: Khabiya Cloth Store | E23: 1000057272 | F23: 21.05.2026 | G23: India Post Parcel Contractual | H23: B2C | I23: Ayush Gupta | J23: Advance
B24: 21 | C24: Ratlam | D24: chirag prodocut | E24: 1254012899 | F24: 46266 | G24: India Post Parcel Contractual | H24: B2C | I24: Ashok Jatiya | J24: Advance
B25: 22 | C25: Ratlam
B26: 23 | C26: Ratlam
B27: 24 | C27: Ratlam
B28: 25 | C28: Ratlam

Sheet Sehore
F2: From Date 01.04.2026 to 31.08.2026
B3: S.No. | C3: Division | D3: Name of Customer | E3: Customer ID | F3: Date of Onboarding | G3: Product Type | H3: B2B Or B2C | I3: Name of ME Who Onboarded | J3: Customer Type Advance/ BNPL
B4: 1 | C4: Sehore | D4: SARTHAK ENTERPRISES | E4: 1131913090 | F4: 10.09.2026 | H4: B2C | I4: HEMANT BAGHEL | J4: Advance
B5: 2 | C5: Sehore | D5: JADUI DHAGE | E5: 1978020115 | F5: 10.09.2026 | H5: B2C | I5: HEMANT BAGHEL | J5: Advance
B6: 3 | C6: Sehore | D6: Union Bank of India | E6: 1634270893 | F6: 03.09.2026 | H6: B2C | I6: DEEPIKA VERMA | J6: BNPL
B7: 4 | C7: Sehore | D7: State Bank of India | E7: 1549258110 | F7: 03.09.2026 | H7: B2C | I7: DEEPIKA VERMA | J7: BNPL
B8: 5 | C8: Sehore | D8: Spare Outlet Krishna Soni | E8: 1840236106 | F8: 02.09.2026 | H8: B2C | I8: NEELESH VERMA | J8: Advance
B9: 6 | C9: Sehore | D9: Amit Raj Singh Kushwah | E9: 1905833890 | F9: 02.09.2026 | H9: B2C | I9: NEELESH VERMA | J9: Advance
B10: 7 | C10: Sehore | D10: Divya Gound | E10: 1353715832 | F10: 17.08.2026 | H10: B2C | I10: NEELESH VERMA | J10: Advance
B11: 8 | C11: Sehore | D11: punam rathore | E11: 1404019518 | F11: 16.08.2026 | H11: B2C | I11: HEMANT BAGHEL | J11: Advance
B12: 9 | C12: Sehore | D12: STATE BANK OF INDIA | E12: 1811627323 | F12: 25.08.2026 | H12: B2C | I12: NEELESH VERMA | J12: BNPL
B13: 10 | C13: Sehore | D13: Shree Ji Collection | E13: 1357785958 | F13: 19.08.2026 | H13: B2C | I13: NEELESH VERMA | J13: Advance
B14: 11 | C14: Sehore | D14: Ashu Collection | E14: 1605992803 | F14: 19.08.2026 | H14: B2C | I14: NEELESH VERMA | J14: Advance
B15: 12 | C15: Sehore | D15: Shivna Prakashan | E15: 1662698556 | F15: 14.08.2026 | H15: B2C | I15: HEMANT BAGHEL | J15: Advance
... B59: 56 | C59: Sehore | D59: nayanthara showroom | E59: 1436142823 | F59: 29.09.2026 | H59: B2C | I59: Rajendra pushpad | J59: Advance

Sheet Sheet11

Sheet Ujjain
F2: From Date 01.04.2026 to 31.08.2026
B3: S.No. | C3: Division | D3: Name of Customer | E3: Customer ID | F3: Date of Onboarding | G3: Product Type | H3: B2B Or B2C | I3: Name of ME Who Onboarded | J3: Customer Type Advance/ BNPL
B4: 1 | C4: Ujjain | D4: shakha prabandhak union bank of india | E4: 1841104004 | F4: 46111 | G4: bnpl-speed post | H4: B2C | I4: Anil kumar kayasth
B5: 2 | C5: Ujjain | D5: Shakha prabandhak mohday bhartiy state bankn agar | E5: 1634558796 | F5: 46118 | G5: bnpl-speed post | H5: B2C | I5: Anil kumar kayasth
B6: 3 | C6: Ujjain | D6: Bal krishna veshnav jay jagnant courier | E6: 1715418519 | F6: 46163 | G6: advance customer | H6: B2C | I6: Anil kumar kayasth
B7: 4 | C7: Ujjain | D7: shakha prabandhak mohday kenra bank agar | E7: 1413997724 | F7: 46163 | G7: bnpl-speed post | H7: B2C | I7: Anil kumar kayasth
B8: 5 | C8: Ujjain | D8: shakha prabandhak idbi bank kota road agar | E8: 1932597043 | F8: 46168 | G8: bnpl-speed post | H8: B2C | I8: Anil kumar kayasth
B9: 6 | C9: Ujjain | D9: Principal mohday kendriy vidhyalay agar | E9: 1762876916 | F9: 46181 | G9: bnpl-speed post | H9: B2C | I9: Anil kumar kayasth
B10: 7 | C10: Ujjain | D10: Principal politachnical college ujjain road agar | E10: 1250783523 | F10: 46202 | G10: bnpl-speed post | H10: B2C | I10: Anil kumar kayasth
B11: 8 | C11: Ujjain | D11: Shakha prabandhak bank of india soyatkalan | E11: 1100308643 | F11: 46233 | G11: bnpl-speed post | H11: B2C | I11: Anil kumar kayasth
B12: 9 | C12: Ujjain | D12: Shakha prabandhak bhartiya state bank soyatkalan | E12: 1982377158 | F12: 46233 | G12: bnpl-speed post | H12: B2C | I12: Anil kumar kayasth
B13: 10 | C13: Ujjain | D13: Shakha prabandhak bhartiya state bank barode | E13: 1866594362 | F13: 46233 | G13: bnpl-speed post | H13: B2C | I13: Anil kumar kayasth
B14: 11 | C14: Ujjain | D14: Shakha prabandhak bank of india barode | E14: 1959590361 | F14: 46233 | G14: bnpl-speed post | H14: B2C | I14: Anil kumar kayasth
B15: 12 | C15: Ujjain | D15: STATE BANK OF INDIA MAKSI | E15: 1566212097 | F15: 46121 | G15: BNPL speed post | H15: B2C | I15: DURGA SHANKAR GARASIYA
... B26: 23 | C26: Ujjain | D26: INDIAN OVERSEAS BANK | E26: 1285666740 | F26: 46276 | G26: BNPL SPEED | H26: B2C | I26: DURGA SHANKAR GARASIYA
B27: 24 | C27: Ujjain | D27: SHRIJI VASTRALAYA TARANA | E27: 1319447119 | G27: parcel contractual | H27: B2C | I27: DURGA SHANKAR GARASIYA
B28: 25 | C28: Ujjain | D28: RADHIKA SAREE TARANA | E28: 1371033742 | F28: 46239 | G28: parcel contractual | H28: B2C | I28: DURGA SHANKAR GARASIYA
B29: 26 | C29: Ujjain | D29: RADHIKA SAREE MAKSI | E29: 1435967697 | F29: 46247 | G29: parcel contractual | H29: B2C | I29: DURGA SHANKAR GARASIYA
B30: 27 | C30: Ujjain | D30: PAAMAS HL BAL PVT LTD | E30: 1332607573 | F30: 46281 | G30: parcel contractual | H30: B2C | I30: DURGA SHANKAR GARASIYA
B31: 28 | C31: Ujjain | D31: SARTHAK PURFUME SHAJAPUR | E31: 1478845372 | F31: 46256 | G31: parcel contractual | H31: B2C | I31: DURGA SHANKAR GARASIYA
B32: 29 | C32: Ujjain | D32: GETSABACUS SHUJALPUR | E32: 1376577863 | F32: 16.07.26 | G32: ADVANCED CUSTOMER | H32: B2C | I32: HARSHIT PARMAR
B33: 30 | C33: Ujjain | D33: DIWAN SINGH RAJPUT | E33: 1676139920 | F33: 20.07.26 | G33: ADVANCED CUSTOMER | H33: B2C | I33: HARSHIT PARMAR
B34: 31 | C34: Ujjain | D34: SBI POLAI KALAN | E34: 1659474901 | F34: 03.08.26 | G34: BNPL | H34: B2C | I34: HARSHIT PARMAR
B35: 32 | C35: Ujjain | D35: THE GOLDEN STRAW SALSALAI | E35: 1641489596 | F35: 08.08.26 | G35: ADVANCED CUSTOMER | H35: B2C | I35: HARSHIT PARMAR
B36: 33 | C36: Ujjain | D36: BANK OF INDIA SHUJALPUR | E36: 1489575716 | F36: 14.08.26 | G36: BNPL | H36: B2C | I36: HARSHIT PARMAR
B37: 34 | C37: Ujjain | D37: MANISH VISHWAKARMA, SHUJALPUR | E37: 1351269580 | F37: 21.08.26 | G37: ADVANCED CUSTOMER | H37: B2C | I37: HARSHIT PARMAR
B38: 35 | C38: Ujjain | D38: Virendra pa | E38: 1142829004 | F38: 46134 | G38: ADVANCED CUSTOMER | H38: B2C | I38: RAHUL AGRAWAL
B39: 36 | C39: Ujjain | D39: jay makwana | E39: 1186471925 | F39: 46133 | G39: ADVANCED CUSTOMER | H39: B2C | I39: RAHUL AGRAWAL
B40: 37 | C40: Ujjain | D40: Divyanshu Khatri | E40: 1966278010 | F40: 46127 | G40: ADVANCED CUSTOMER | H40: B2C | I40: RAHUL AGRAWAL
B41: 38 | C41: Ujjain | D41: SHRI COLLECTION Customer ID:: | E41: 1869951677 | F41: 46125 | G41: ADVANCED CUSTOMER | H41: B2C | I41: RAHUL AGRAWAL
B42: 39 | C42: Ujjain | D42: MOHIT SINGH PANWAR | E42: 1132441153 | F42: 46123 | G42: ADVANCED CUSTOMER | H42: B2C | I42: RAHUL AGRAWAL
B43: 40 | C43: Ujjain | D43: ANIKET AGRAWAL | E43: 1307425262 | F43: 46122 | G43: ADVANCED CUSTOMER | H43: B2C | I43: RAHUL AGRAWAL
B44: 41 | C44: Ujjain | D44: KUNWAR SA WEDDING STORE | E44: 1663820107 | F44: 46121 | G44: ADVANCED CUSTOMER | H44: B2C | I44: RAHUL AGRAWAL
B45: 42 | C45: Ujjain | D45: TANA BANA BOUTIQUE | E45: 1988426117 | F45: 46114 | G45: ADVANCED CUSTOMER | H45: B2C | I45: RAHUL AGRAWAL
